ERROR:root:Error occurred while running the bot: This event loop is already running
ERROR:root:Error occurred in main while starting the bot: Event loop is closed
ERROR:root:Error occurred while running the bot: This event loop is already running
ERROR:root:Error occurred while running the bot: This event loop is already running
ERROR:root:Error occurred in send_news: cursor already closed
ERROR:root:Error occurred while running the bot: This event loop is already running
ERROR:root:Error occurred in send_news: cursor already closed
ERROR:root:Error occurred while running the bot: This event loop is already running
ERROR:root:Error occurred in send_news: cursor already closed
ERROR:root:Error occurred while running the bot: This event loop is already running
ERROR:root:Error occurred in send_news: cursor already closed
ERROR:root:Error occurred in main while starting the bot: Event loop is closed
ERROR:root:Error occurred in main while starting the bot: There is no current event loop in thread 'MainThread'.
ERROR:root:Error occurred in main while starting the bot: There is no current event loop in thread 'MainThread'.
ERROR:root:Error occurred in main while starting the bot: There is no current event loop in thread 'MainThread'.
ERROR:root:Error occurred while starting the bot: This event loop is already running
ERROR:asyncio:Exception in callback Cron.set_result(<_GatheringFu...ady closed')]>)
handle: <Handle Cron.set_result(<_GatheringFu...ady closed')]>)>
Traceback (most recent call last):
  File "C:\Program Files\WindowsApps\PythonSoftwareFoundation.Python.3.10_3.10.3056.0_x64__qbz5n2kfra8p0\lib\asyncio\events.py", line 80, in _run
    self._context.run(self._callback, *self._args)
  File "D:\Python\MyProjects\TIIAME_NRU\venv\lib\site-packages\aiocron\__init__.py", line 112, in set_result
    raise result
  File "D:\Python\MyProjects\TIIAME_NRU\Bot\main.py", line 221, in cronjob
    cur.execute("SELECT * FROM class_schedule WHERE day = %s AND end_time = %s",
  File "D:\Python\MyProjects\TIIAME_NRU\venv\lib\site-packages\psycopg2\extras.py", line 146, in execute
    return super().execute(query, vars)
psycopg2.InterfaceError: cursor already closed
ERROR:asyncio:Exception in callback Cron.set_result(<_GatheringFu...ady closed')]>)
handle: <Handle Cron.set_result(<_GatheringFu...ady closed')]>)>
Traceback (most recent call last):
  File "C:\Program Files\WindowsApps\PythonSoftwareFoundation.Python.3.10_3.10.3056.0_x64__qbz5n2kfra8p0\lib\asyncio\events.py", line 80, in _run
    self._context.run(self._callback, *self._args)
  File "D:\Python\MyProjects\TIIAME_NRU\venv\lib\site-packages\aiocron\__init__.py", line 112, in set_result
    raise result
  File "D:\Python\MyProjects\TIIAME_NRU\Bot\main.py", line 199, in cronjob
    cur.execute("SELECT * FROM class_schedule WHERE day = %s AND end_time = %s",
  File "D:\Python\MyProjects\TIIAME_NRU\venv\lib\site-packages\psycopg2\extras.py", line 146, in execute
    return super().execute(query, vars)
psycopg2.InterfaceError: cursor already closed
ERROR:root:Error occurred in cmd_start while starting the bot: cursor already closed
ERROR:asyncio:Exception in callback Cron.set_result(<_GatheringFu...ady closed')]>)
handle: <Handle Cron.set_result(<_GatheringFu...ady closed')]>)>
Traceback (most recent call last):
  File "C:\Program Files\WindowsApps\PythonSoftwareFoundation.Python.3.10_3.10.3056.0_x64__qbz5n2kfra8p0\lib\asyncio\events.py", line 80, in _run
    self._context.run(self._callback, *self._args)
  File "D:\Python\MyProjects\TIIAME_NRU\venv\lib\site-packages\aiocron\__init__.py", line 112, in set_result
    raise result
  File "D:\Python\MyProjects\TIIAME_NRU\Bot\main.py", line 199, in cronjob
    cur.execute("SELECT * FROM class_schedule WHERE day = %s AND end_time = %s",
  File "D:\Python\MyProjects\TIIAME_NRU\venv\lib\site-packages\psycopg2\extras.py", line 146, in execute
    return super().execute(query, vars)
psycopg2.InterfaceError: cursor already closed
ERROR:asyncio:Exception in callback Cron.set_result(<_GatheringFu...ady closed')]>)
handle: <Handle Cron.set_result(<_GatheringFu...ady closed')]>)>
Traceback (most recent call last):
  File "C:\Program Files\WindowsApps\PythonSoftwareFoundation.Python.3.10_3.10.3056.0_x64__qbz5n2kfra8p0\lib\asyncio\events.py", line 80, in _run
    self._context.run(self._callback, *self._args)
  File "D:\Python\MyProjects\TIIAME_NRU\venv\lib\site-packages\aiocron\__init__.py", line 112, in set_result
    raise result
  File "D:\Python\MyProjects\TIIAME_NRU\Bot\main.py", line 199, in cronjob
    cur.execute("SELECT * FROM class_schedule WHERE day = %s AND end_time = %s",
  File "D:\Python\MyProjects\TIIAME_NRU\venv\lib\site-packages\psycopg2\extras.py", line 146, in execute
    return super().execute(query, vars)
psycopg2.InterfaceError: cursor already closed
ERROR:asyncio:Exception in callback Cron.set_result(<_GatheringFu...ady closed')]>)
handle: <Handle Cron.set_result(<_GatheringFu...ady closed')]>)>
Traceback (most recent call last):
  File "C:\Program Files\WindowsApps\PythonSoftwareFoundation.Python.3.10_3.10.3056.0_x64__qbz5n2kfra8p0\lib\asyncio\events.py", line 80, in _run
    self._context.run(self._callback, *self._args)
  File "D:\Python\MyProjects\TIIAME_NRU\venv\lib\site-packages\aiocron\__init__.py", line 112, in set_result
    raise result
  File "D:\Python\MyProjects\TIIAME_NRU\Bot\main.py", line 199, in cronjob
    cur.execute("SELECT * FROM class_schedule WHERE day = %s AND end_time = %s",
  File "D:\Python\MyProjects\TIIAME_NRU\venv\lib\site-packages\psycopg2\extras.py", line 146, in execute
    return super().execute(query, vars)
psycopg2.InterfaceError: cursor already closed
ERROR:asyncio:Exception in callback Cron.set_result(<_GatheringFu...ady closed')]>)
handle: <Handle Cron.set_result(<_GatheringFu...ady closed')]>)>
Traceback (most recent call last):
  File "C:\Program Files\WindowsApps\PythonSoftwareFoundation.Python.3.10_3.10.3056.0_x64__qbz5n2kfra8p0\lib\asyncio\events.py", line 80, in _run
    self._context.run(self._callback, *self._args)
  File "D:\Python\MyProjects\TIIAME_NRU\venv\lib\site-packages\aiocron\__init__.py", line 112, in set_result
    raise result
  File "D:\Python\MyProjects\TIIAME_NRU\Bot\main.py", line 199, in cronjob
    cur.execute("SELECT * FROM class_schedule WHERE day = %s AND end_time = %s",
  File "D:\Python\MyProjects\TIIAME_NRU\venv\lib\site-packages\psycopg2\extras.py", line 146, in execute
    return super().execute(query, vars)
psycopg2.InterfaceError: cursor already closed
ERROR:root:Error occurred in send_news: [Errno 2] No such file or directory: 'news/507.png'
ERROR:asyncio:Exception in callback Cron.set_result(<_GatheringFu...ady closed')]>)
handle: <Handle Cron.set_result(<_GatheringFu...ady closed')]>)>
Traceback (most recent call last):
  File "C:\Program Files\WindowsApps\PythonSoftwareFoundation.Python.3.10_3.10.3056.0_x64__qbz5n2kfra8p0\lib\asyncio\events.py", line 80, in _run
    self._context.run(self._callback, *self._args)
  File "D:\Python\MyProjects\TIIAME_NRU\venv\lib\site-packages\aiocron\__init__.py", line 112, in set_result
    raise result
  File "D:\Python\MyProjects\TIIAME_NRU\Bot\main.py", line 221, in cronjob
    cur.execute("SELECT * FROM class_schedule WHERE day = %s AND end_time = %s",
  File "D:\Python\MyProjects\TIIAME_NRU\venv\lib\site-packages\psycopg2\extras.py", line 146, in execute
    return super().execute(query, vars)
psycopg2.InterfaceError: cursor already closed
ERROR:asyncio:Exception in callback Cron.set_result(<_GatheringFu...ady closed')]>)
handle: <Handle Cron.set_result(<_GatheringFu...ady closed')]>)>
Traceback (most recent call last):
  File "C:\Program Files\WindowsApps\PythonSoftwareFoundation.Python.3.10_3.10.3056.0_x64__qbz5n2kfra8p0\lib\asyncio\events.py", line 80, in _run
    self._context.run(self._callback, *self._args)
  File "D:\Python\MyProjects\TIIAME_NRU\venv\lib\site-packages\aiocron\__init__.py", line 112, in set_result
    raise result
  File "D:\Python\MyProjects\TIIAME_NRU\Bot\main.py", line 221, in cronjob
    cur.execute("SELECT * FROM class_schedule WHERE day = %s AND end_time = %s",
  File "D:\Python\MyProjects\TIIAME_NRU\venv\lib\site-packages\psycopg2\extras.py", line 146, in execute
    return super().execute(query, vars)
psycopg2.InterfaceError: cursor already closed
ERROR:asyncio:Exception in callback Cron.set_result(<_GatheringFu...ady closed')]>)
handle: <Handle Cron.set_result(<_GatheringFu...ady closed')]>)>
Traceback (most recent call last):
  File "C:\Program Files\WindowsApps\PythonSoftwareFoundation.Python.3.10_3.10.3056.0_x64__qbz5n2kfra8p0\lib\asyncio\events.py", line 80, in _run
    self._context.run(self._callback, *self._args)
  File "D:\Python\MyProjects\TIIAME_NRU\venv\lib\site-packages\aiocron\__init__.py", line 112, in set_result
    raise result
  File "D:\Python\MyProjects\TIIAME_NRU\Bot\main.py", line 221, in cronjob
    cur.execute("SELECT * FROM class_schedule WHERE day = %s AND end_time = %s",
  File "D:\Python\MyProjects\TIIAME_NRU\venv\lib\site-packages\psycopg2\extras.py", line 146, in execute
    return super().execute(query, vars)
psycopg2.InterfaceError: cursor already closed
ERROR:asyncio:Exception in callback Cron.set_result(<_GatheringFu...ady closed')]>)
handle: <Handle Cron.set_result(<_GatheringFu...ady closed')]>)>
Traceback (most recent call last):
  File "C:\Program Files\WindowsApps\PythonSoftwareFoundation.Python.3.10_3.10.3056.0_x64__qbz5n2kfra8p0\lib\asyncio\events.py", line 80, in _run
    self._context.run(self._callback, *self._args)
  File "D:\Python\MyProjects\TIIAME_NRU\venv\lib\site-packages\aiocron\__init__.py", line 112, in set_result
    raise result
  File "D:\Python\MyProjects\TIIAME_NRU\Bot\main.py", line 221, in cronjob
    @aiocron.crontab('* * * * *')
  File "D:\Python\MyProjects\TIIAME_NRU\venv\lib\site-packages\psycopg2\extras.py", line 146, in execute
    return super().execute(query, vars)
psycopg2.InterfaceError: cursor already closed
ERROR:root:File not found: news/507.png
ERROR:root:File not found: news/507.png
ERROR:root:File not found: news/507.png
ERROR:asyncio:Exception in callback Cron.set_result(<_GatheringFu...ady closed')]>)
handle: <Handle Cron.set_result(<_GatheringFu...ady closed')]>)>
Traceback (most recent call last):
  File "C:\Program Files\WindowsApps\PythonSoftwareFoundation.Python.3.10_3.10.3056.0_x64__qbz5n2kfra8p0\lib\asyncio\events.py", line 80, in _run
    self._context.run(self._callback, *self._args)
  File "D:\Python\MyProjects\TIIAME_NRU\venv\lib\site-packages\aiocron\__init__.py", line 112, in set_result
    raise result
  File "D:\Python\MyProjects\TIIAME_NRU\Bot\main.py", line 224, in cronjob
    cur.execute("SELECT * FROM class_schedule WHERE day = %s AND end_time = %s",
  File "D:\Python\MyProjects\TIIAME_NRU\venv\lib\site-packages\psycopg2\extras.py", line 146, in execute
    return super().execute(query, vars)
psycopg2.InterfaceError: cursor already closed
ERROR:root:File not found: media/news/news/507.png
ERROR:root:File not found: media/news/news/507.png
ERROR:root:File not found: media/news/news/507.png
ERROR:asyncio:Exception in callback Cron.set_result(<_GatheringFu...ady closed')]>)
handle: <Handle Cron.set_result(<_GatheringFu...ady closed')]>)>
Traceback (most recent call last):
  File "C:\Program Files\WindowsApps\PythonSoftwareFoundation.Python.3.10_3.10.3056.0_x64__qbz5n2kfra8p0\lib\asyncio\events.py", line 80, in _run
    self._context.run(self._callback, *self._args)
  File "D:\Python\MyProjects\TIIAME_NRU\venv\lib\site-packages\aiocron\__init__.py", line 112, in set_result
    raise result
  File "D:\Python\MyProjects\TIIAME_NRU\Bot\main.py", line 224, in cronjob
    cur.execute("SELECT * FROM class_schedule WHERE day = %s AND end_time = %s",
  File "D:\Python\MyProjects\TIIAME_NRU\venv\lib\site-packages\psycopg2\extras.py", line 146, in execute
    return super().execute(query, vars)
psycopg2.InterfaceError: cursor already closed
ERROR:root:Error occurred in cmd_start while starting the bot: cursor already closed
ERROR:root:Error occurred in cmd_start while starting the bot: cursor already closed
ERROR:root:Error occurred in cmd_start while starting the bot: cursor already closed
ERROR:asyncio:Exception in callback Cron.set_result(<_GatheringFu...ady closed')]>)
handle: <Handle Cron.set_result(<_GatheringFu...ady closed')]>)>
Traceback (most recent call last):
  File "C:\Program Files\WindowsApps\PythonSoftwareFoundation.Python.3.10_3.10.3056.0_x64__qbz5n2kfra8p0\lib\asyncio\events.py", line 80, in _run
    self._context.run(self._callback, *self._args)
  File "D:\Python\MyProjects\TIIAME_NRU\venv\lib\site-packages\aiocron\__init__.py", line 112, in set_result
    raise result
  File "D:\Python\MyProjects\TIIAME_NRU\Bot\main.py", line 224, in cronjob
    cur.execute("SELECT * FROM class_schedule WHERE day = %s AND end_time = %s",
  File "D:\Python\MyProjects\TIIAME_NRU\venv\lib\site-packages\psycopg2\extras.py", line 146, in execute
    return super().execute(query, vars)
psycopg2.InterfaceError: cursor already closed
ERROR:asyncio:Exception in callback Cron.set_result(<_GatheringFu...ady closed')]>)
handle: <Handle Cron.set_result(<_GatheringFu...ady closed')]>)>
Traceback (most recent call last):
  File "C:\Program Files\WindowsApps\PythonSoftwareFoundation.Python.3.10_3.10.3056.0_x64__qbz5n2kfra8p0\lib\asyncio\events.py", line 80, in _run
    self._context.run(self._callback, *self._args)
  File "D:\Python\MyProjects\TIIAME_NRU\venv\lib\site-packages\aiocron\__init__.py", line 112, in set_result
    raise result
  File "D:\Python\MyProjects\TIIAME_NRU\Bot\main.py", line 224, in cronjob
    cur.execute("SELECT * FROM class_schedule WHERE day = %s AND end_time = %s",
  File "D:\Python\MyProjects\TIIAME_NRU\venv\lib\site-packages\psycopg2\extras.py", line 146, in execute
    return super().execute(query, vars)
psycopg2.InterfaceError: cursor already closed
ERROR:root:File not found: media/news/news/507.png
ERROR:root:File not found: media/news/news/506.png
ERROR:root:File not found: media/news/news/507.png
ERROR:root:File not found: media/news/news/506.png
ERROR:root:File not found: media/news/news/507.png
ERROR:root:File not found: media/news/news/506.png
ERROR:root:Error occurred in send_news: Message caption is too long
ERROR:root:File not found: media/news/news/IMG_20230621_214058_905.jpg
ERROR:root:File not found: media/news/news/elon2_14.png
ERROR:root:File not found: media/news/news/IMG_20230621_214058_905.jpg
ERROR:root:File not found: media/news/news/elon2_14.png
ERROR:root:File not found: media/news/news/IMG_20230621_214058_905.jpg
ERROR:root:File not found: media/news/news/elon2_14.png
ERROR:root:File not found: media/news/news/elon2_14_rt97f7D.png
ERROR:root:File not found: media/news/news/elon2_14_rt97f7D.png
ERROR:root:File not found: media/news/news/elon2_14_rt97f7D.png
ERROR:root:File not found: media/news/news/elon2_14.png
ERROR:root:File not found: media/news/news/elon2_14.png
ERROR:root:File not found: media/news/news/elon2_14.png
ERROR:root:File not found: media/news/news/elon2_14.png
ERROR:root:File not found: media/news/news/elon2_14.png
ERROR:root:File not found: media/news/news/elon2_14.png
ERROR:root:File not found: media/news/Tiiame_bg.png
